<?xml version="1.0" ?>
<!-- =================================================================================== -->
<!-- |    This document was autogenerated by xacro from /home/r/silver_ws/src/silverhand_rover_control/silverhand_rover_description/urdf/silverhand_rover_model.urdf.xacro | -->
<!-- |    EDITING THIS FILE BY HAND IS NOT RECOMMENDED                                 | -->
<!-- =================================================================================== -->
<robot name="silverhand_rover">
  <!-- ===================== -->
  <!-- Общие параметры       -->
  <!-- ===================== -->
  <!-- ===================== -->
  <!-- Параметры компоновки  -->
  <!-- ===================== -->
  <!-- Система координат:
       x - вперед
       y - влево
       z - вверх
  -->
  <!-- ===================== -->
  <!-- Сдвиги STL внутри link -->
  <!-- ===================== -->
  <!-- Начни с нулей. Потом правь именно их,
       если сам mesh внутри link сидит криво. -->
  <!-- Если правая сторона окажется вывернутой,
       попробуй для правой стороны в visual поставить:
       0 ${PI} 0
       или
       0 0 ${PI}
  -->
  <!-- ===================== -->
  <!-- Материалы             -->
  <!-- ===================== -->
  <material name="gray">
    <color rgba="0.75 0.75 0.75 1.0"/>
  </material>
  <material name="dark">
    <color rgba="0.25 0.25 0.25 1.0"/>
  </material>
  <!-- ===================== -->
  <!-- Макросы               -->
  <!-- ===================== -->
  <!-- ===================== -->
  <!-- База                  -->
  <!-- ===================== -->
  <link name="base_footprint"/>
  <joint name="base_footprint_to_base_link_joint" type="fixed">
    <parent link="base_footprint"/>
    <child link="base_link"/>
    <origin rpy="0 0 0" xyz="0 0 0.350738"/>
  </joint>
  <link name="base_link">
    <visual>
      <origin rpy="1.5707963267948966 0 1.5707963267948966" xyz="-0.017 0 -0.162"/>
      <geometry>
        <mesh filename="package://silverhand_rover_description/meshes/Body.stl" scale="0.001 0.001 0.001"/>
      </geometry>
      <material name="gray"/>
    </visual>
    <collision>
      <origin rpy="1.5707963267948966 0 1.5707963267948966" xyz="-0.017 0 -0.162"/>
      <geometry>
        <mesh filename="package://silverhand_rover_description/meshes/Body.stl" scale="0.001 0.001 0.001"/>
      </geometry>
    </collision>
    <inertial>
      <origin rpy="0 0 0" xyz="0 0 0"/>
      <mass value="5.0"/>
      <inertia ixx="0.19266666666666665" ixy="0.0" ixz="0.0" iyy="0.39533333333333337" iyz="0.0" izz="0.5026666666666667"/>
    </inertial>
  </link>
  <!-- Центральный visual-узел.
       Пока просто декоративно/визуально.
       Если потом захочешь честную механику дифференциала,
       его уже можно будет перестроить. -->
  <link name="differential_visual_link">
    <visual>
      <origin rpy="1.5707963267948966 0 1.5707963267948966" xyz="0 0 0"/>
      <geometry>
        <mesh filename="package://silverhand_rover_description/meshes/Differential.stl" scale="0.001 0.001 0.001"/>
      </geometry>
      <material name="dark"/>
    </visual>
    <collision>
      <origin rpy="1.5707963267948966 0 1.5707963267948966" xyz="0 0 0"/>
      <geometry>
        <mesh filename="package://silverhand_rover_description/meshes/Differential.stl" scale="0.001 0.001 0.001"/>
      </geometry>
    </collision>
    <inertial>
      <origin rpy="0 0 0" xyz="0 0 0"/>
      <mass value="0.8"/>
      <inertia ixx="0.029226666666666668" ixy="0.0" ixz="0.0" iyy="0.02402666666666667" iyz="0.0" izz="0.005253333333333335"/>
    </inertial>
  </link>
  <joint name="base_to_differential_visual_joint" type="fixed">
    <parent link="base_link"/>
    <child link="differential_visual_link"/>
    <origin rpy="0 0 0" xyz="-0.1769 0 0.111"/>
  </joint>
  <link name="left_leg_visual_link">
    <visual>
      <origin rpy="1.5707963267948966 0 4.71238898038469" xyz="0 0 0"/>
      <geometry>
        <mesh filename="package://silverhand_rover_description/meshes/Leg.stl" scale="0.001 0.001 0.001"/>
      </geometry>
      <material name="gray"/>
    </visual>
    <collision>
      <origin rpy="1.5707963267948966 0 4.71238898038469" xyz="0 0 0"/>
      <geometry>
        <mesh filename="package://silverhand_rover_description/meshes/Leg.stl" scale="0.001 0.001 0.001"/>
      </geometry>
    </collision>
  </link>
  <joint name="base_to_left_leg_visual_joint" type="fixed">
    <parent link="base_link"/>
    <child link="left_leg_visual_link"/>
    <origin rpy="0 0 0" xyz="0.053 0.285 -0.029"/>
  </joint>
  <link name="right_leg_visual_link">
    <visual>
      <origin rpy="1.5707963267948966 0 4.71238898038469" xyz="0 0 0"/>
      <geometry>
        <mesh filename="package://silverhand_rover_description/meshes/Leg.stl" scale="0.001 0.001 0.001"/>
      </geometry>
      <material name="gray"/>
    </visual>
    <collision>
      <origin rpy="1.5707963267948966 0 4.71238898038469" xyz="0 0 0"/>
      <geometry>
        <mesh filename="package://silverhand_rover_description/meshes/Leg.stl" scale="0.001 0.001 0.001"/>
      </geometry>
    </collision>
  </link>
  <joint name="base_to_right_leg_visual_joint" type="fixed">
    <parent link="base_link"/>
    <child link="right_leg_visual_link"/>
    <origin rpy="0 0 0" xyz="0.053 -0.285 -0.029"/>
  </joint>
  <!-- ===================== -->
  <!-- Левая и правая сторона -->
  <!-- ===================== -->
  <!-- ROCKER -->
  <link name="left_rocker_link">
    <inertial>
      <origin rpy="0 0 0" xyz="0 0 0"/>
      <mass value="0.7"/>
      <inertia ixx="0.0016391666666666666" ixy="0.0" ixz="0.0" iyy="0.01082666666666667" iyz="0.0" izz="0.009479166666666669"/>
    </inertial>
  </link>
  <joint name="base_to_left_rocker_joint" type="revolute">
    <parent link="base_link"/>
    <child link="left_rocker_link"/>
    <origin rpy="0 0 0" xyz="0.1 0.355 -0.1"/>
    <!-- Rocker качается в продольной плоскости -->
    <axis xyz="0 1 0"/>
    <limit effort="50" lower="-1.2" upper="1.2" velocity="2.0"/>
    <dynamics damping="0.5" friction="0.1"/>
  </joint>
  <!-- BOGIE -->
  <link name="left_bogie_link">
    <inertial>
      <origin rpy="0 0 0" xyz="0 0 0"/>
      <mass value="0.6"/>
      <inertia ixx="0.001105" ixy="0.0" ixz="0.0" iyy="0.007104999999999999" iyz="0.0" izz="0.006249999999999999"/>
    </inertial>
  </link>
  <joint name="left_rocker_to_left_bogie_joint" type="revolute">
    <parent link="left_rocker_link"/>
    <child link="left_bogie_link"/>
    <origin rpy="0 0 0" xyz="-0.25 0.0 0.0"/>
    <axis xyz="0 1 0"/>
    <limit effort="50" lower="-1.2" upper="1.2" velocity="2.0"/>
    <dynamics damping="0.5" friction="0.1"/>
  </joint>
  <link name="left_front_wheel_link">
    <visual>
      <origin rpy="-1.5707963267948966 -0.890121786 0" xyz="-0.10706 -0.088 0.09654"/>
      <geometry>
        <mesh filename="package://silverhand_rover_description/meshes/Wheel.stl" scale="0.001 0.001 0.001"/>
      </geometry>
      <material name="dark"/>
    </visual>
    <collision>
      <origin rpy="-1.5707963267948966 -0.890121786 0" xyz="-0.10706 -0.088 0.09654"/>
      <geometry>
        <mesh filename="package://silverhand_rover_description/meshes/Wheel.stl" scale="0.001 0.001 0.001"/>
      </geometry>
    </collision>
    <inertial>
      <origin rpy="0 0 0" xyz="0 0 0"/>
      <mass value="0.35"/>
      <!-- Цилиндр с осью вдоль Y -->
      <inertia ixx="0.002461982541666667" ixy="0.0" ixz="0.0" iyy="0.0028181317500000007" iyz="0.0" izz="0.002461982541666667"/>
    </inertial>
  </link>
  <joint name="left_front_wheel_joint" type="continuous">
    <parent link="left_rocker_link"/>
    <child link="left_front_wheel_link"/>
    <origin rpy="0 0 0" xyz="0.3 0.0 -0.22"/>
    <axis xyz="0 1 0"/>
    <dynamics damping="0.2" friction="0.05"/>
  </joint>
  <link name="left_middle_wheel_link">
    <visual>
      <origin rpy="-1.5707963267948966 -0.928081215 0" xyz="0.10790 -0.088 0.09683"/>
      <geometry>
        <mesh filename="package://silverhand_rover_description/meshes/Wheel.stl" scale="0.001 0.001 0.001"/>
      </geometry>
      <material name="dark"/>
    </visual>
    <collision>
      <origin rpy="-1.5707963267948966 -0.928081215 0" xyz="0.10790 -0.088 0.09683"/>
      <geometry>
        <mesh filename="package://silverhand_rover_description/meshes/Wheel.stl" scale="0.001 0.001 0.001"/>
      </geometry>
    </collision>
    <inertial>
      <origin rpy="0 0 0" xyz="0 0 0"/>
      <mass value="0.35"/>
      <!-- Цилиндр с осью вдоль Y -->
      <inertia ixx="0.002461982541666667" ixy="0.0" ixz="0.0" iyy="0.0028181317500000007" iyz="0.0" izz="0.002461982541666667"/>
    </inertial>
  </link>
  <joint name="left_middle_wheel_joint" type="continuous">
    <parent link="left_bogie_link"/>
    <child link="left_middle_wheel_link"/>
    <origin rpy="0 0 0" xyz="0.02 0.0 -0.22"/>
    <axis xyz="0 1 0"/>
    <dynamics damping="0.2" friction="0.05"/>
  </joint>
  <link name="left_rear_wheel_link">
    <visual>
      <origin rpy="-1.5707963267948966 0.869224977 0" xyz="0.14377 -0.088 0.09623"/>
      <geometry>
        <mesh filename="package://silverhand_rover_description/meshes/Wheel.stl" scale="0.001 0.001 0.001"/>
      </geometry>
      <material name="dark"/>
    </visual>
    <collision>
      <origin rpy="-1.5707963267948966 0.869224977 0" xyz="0.14377 -0.088 0.09623"/>
      <geometry>
        <mesh filename="package://silverhand_rover_description/meshes/Wheel.stl" scale="0.001 0.001 0.001"/>
      </geometry>
    </collision>
    <inertial>
      <origin rpy="0 0 0" xyz="0 0 0"/>
      <mass value="0.35"/>
      <!-- Цилиндр с осью вдоль Y -->
      <inertia ixx="0.002461982541666667" ixy="0.0" ixz="0.0" iyy="0.0028181317500000007" iyz="0.0" izz="0.002461982541666667"/>
    </inertial>
  </link>
  <joint name="left_rear_wheel_joint" type="continuous">
    <parent link="left_bogie_link"/>
    <child link="left_rear_wheel_link"/>
    <origin rpy="0 0 0" xyz="-0.32 0.0 -0.22"/>
    <axis xyz="0 1 0"/>
    <dynamics damping="0.2" friction="0.05"/>
  </joint>
  <!-- ROCKER -->
  <link name="right_rocker_link">
    <inertial>
      <origin rpy="0 0 0" xyz="0 0 0"/>
      <mass value="0.7"/>
      <inertia ixx="0.0016391666666666666" ixy="0.0" ixz="0.0" iyy="0.01082666666666667" iyz="0.0" izz="0.009479166666666669"/>
    </inertial>
  </link>
  <joint name="base_to_right_rocker_joint" type="revolute">
    <parent link="base_link"/>
    <child link="right_rocker_link"/>
    <origin rpy="0 0 0" xyz="0.1 -0.355 -0.1"/>
    <!-- Rocker качается в продольной плоскости -->
    <axis xyz="0 1 0"/>
    <limit effort="50" lower="-1.2" upper="1.2" velocity="2.0"/>
    <dynamics damping="0.5" friction="0.1"/>
  </joint>
  <!-- BOGIE -->
  <link name="right_bogie_link">
    <inertial>
      <origin rpy="0 0 0" xyz="0 0 0"/>
      <mass value="0.6"/>
      <inertia ixx="0.001105" ixy="0.0" ixz="0.0" iyy="0.007104999999999999" iyz="0.0" izz="0.006249999999999999"/>
    </inertial>
  </link>
  <joint name="right_rocker_to_right_bogie_joint" type="revolute">
    <parent link="right_rocker_link"/>
    <child link="right_bogie_link"/>
    <origin rpy="0 0 0" xyz="-0.25 0.0 0.0"/>
    <axis xyz="0 1 0"/>
    <limit effort="50" lower="-1.2" upper="1.2" velocity="2.0"/>
    <dynamics damping="0.5" friction="0.1"/>
  </joint>
  <link name="right_front_wheel_link">
    <visual>
      <origin rpy="-1.5707963267948966 0.890121786 3.141592653589793" xyz="-0.10706 0.088 0.09654"/>
      <geometry>
        <mesh filename="package://silverhand_rover_description/meshes/Wheel.stl" scale="0.001 0.001 0.001"/>
      </geometry>
      <material name="dark"/>
    </visual>
    <collision>
      <origin rpy="-1.5707963267948966 0.890121786 3.141592653589793" xyz="-0.10706 0.088 0.09654"/>
      <geometry>
        <mesh filename="package://silverhand_rover_description/meshes/Wheel.stl" scale="0.001 0.001 0.001"/>
      </geometry>
    </collision>
    <inertial>
      <origin rpy="0 0 0" xyz="0 0 0"/>
      <mass value="0.35"/>
      <!-- Цилиндр с осью вдоль Y -->
      <inertia ixx="0.002461982541666667" ixy="0.0" ixz="0.0" iyy="0.0028181317500000007" iyz="0.0" izz="0.002461982541666667"/>
    </inertial>
  </link>
  <joint name="right_front_wheel_joint" type="continuous">
    <parent link="right_rocker_link"/>
    <child link="right_front_wheel_link"/>
    <origin rpy="0 0 0" xyz="0.3 0.0 -0.22"/>
    <axis xyz="0 1 0"/>
    <dynamics damping="0.2" friction="0.05"/>
  </joint>
  <link name="right_middle_wheel_link">
    <visual>
      <origin rpy="-1.5707963267948966 0.928081215 3.141592653589793" xyz="0.10790 0.088 0.09683"/>
      <geometry>
        <mesh filename="package://silverhand_rover_description/meshes/Wheel.stl" scale="0.001 0.001 0.001"/>
      </geometry>
      <material name="dark"/>
    </visual>
    <collision>
      <origin rpy="-1.5707963267948966 0.928081215 3.141592653589793" xyz="0.10790 0.088 0.09683"/>
      <geometry>
        <mesh filename="package://silverhand_rover_description/meshes/Wheel.stl" scale="0.001 0.001 0.001"/>
      </geometry>
    </collision>
    <inertial>
      <origin rpy="0 0 0" xyz="0 0 0"/>
      <mass value="0.35"/>
      <!-- Цилиндр с осью вдоль Y -->
      <inertia ixx="0.002461982541666667" ixy="0.0" ixz="0.0" iyy="0.0028181317500000007" iyz="0.0" izz="0.002461982541666667"/>
    </inertial>
  </link>
  <joint name="right_middle_wheel_joint" type="continuous">
    <parent link="right_bogie_link"/>
    <child link="right_middle_wheel_link"/>
    <origin rpy="0 0 0" xyz="0.02 0.0 -0.22"/>
    <axis xyz="0 1 0"/>
    <dynamics damping="0.2" friction="0.05"/>
  </joint>
  <link name="right_rear_wheel_link">
    <visual>
      <origin rpy="-1.5707963267948966 -0.869224977 3.141592653589793" xyz="0.14377 0.088 0.09623"/>
      <geometry>
        <mesh filename="package://silverhand_rover_description/meshes/Wheel.stl" scale="0.001 0.001 0.001"/>
      </geometry>
      <material name="dark"/>
    </visual>
    <collision>
      <origin rpy="-1.5707963267948966 -0.869224977 3.141592653589793" xyz="0.14377 0.088 0.09623"/>
      <geometry>
        <mesh filename="package://silverhand_rover_description/meshes/Wheel.stl" scale="0.001 0.001 0.001"/>
      </geometry>
    </collision>
    <inertial>
      <origin rpy="0 0 0" xyz="0 0 0"/>
      <mass value="0.35"/>
      <!-- Цилиндр с осью вдоль Y -->
      <inertia ixx="0.002461982541666667" ixy="0.0" ixz="0.0" iyy="0.0028181317500000007" iyz="0.0" izz="0.002461982541666667"/>
    </inertial>
  </link>
  <joint name="right_rear_wheel_joint" type="continuous">
    <parent link="right_bogie_link"/>
    <child link="right_rear_wheel_link"/>
    <origin rpy="0 0 0" xyz="-0.32 0.0 -0.22"/>
    <axis xyz="0 1 0"/>
    <dynamics damping="0.2" friction="0.05"/>
  </joint>
</robot>
