<?xml version="1.0" ?>
<!-- =================================================================================== -->
<!-- |    This document was autogenerated by xacro from /home/robot/silver_ws/src/silverhand_arm_model/urdf/silverhand_arm3.urdf.xacro | -->
<!-- |    EDITING THIS FILE BY HAND IS NOT RECOMMENDED                                 | -->
<!-- =================================================================================== -->
<robot name="silverhand">
  <link name="base_link"/>
  <link name="arm_root_link">
    <inertial>
      <origin rpy="0 0 0" xyz="0 0.054174 0.038824"/>
      <mass value="0.7102"/>
      <inertia ixx="0.0039943" ixy="3.697E-07" ixz="-5.7364E-08" iyy="0.0014946" iyz="-0.00036051" izz="0.0042554"/>
    </inertial>
    <visual>
      <origin rpy="0 0 0" xyz="0 0 0"/>
      <geometry>
        <mesh filename="package://silverhand_arm_model/meshes/base_link.STL"/>
      </geometry>
      <material name="">
        <color rgba="0.80 0.80 0.82 1"/>
      </material>
    </visual>
    <collision>
      <origin rpy="0 0 0" xyz="0 0 0"/>
      <geometry>
        <mesh filename="package://silverhand_arm_model/meshes/base_link.STL"/>
      </geometry>
    </collision>
  </link>
  <joint name="arm_root_joint" type="fixed">
    <origin rpy="0 0 1.5708" xyz="0 0 0"/>
    <parent link="base_link"/>
    <child link="arm_root_link"/>
  </joint>
  <link name="link_1">
    <inertial>
      <origin rpy="0 0 0" xyz="-0.022706 0.04294 -0.12205"/>
      <mass value="0.88065"/>
      <inertia ixx="0.0034" ixy="0.00042296" ixz="-0.00089231" iyy="0.0041778" iyz="0.0010848" izz="0.0027077"/>
    </inertial>
    <visual>
      <origin rpy="0 0 0" xyz="0 0 0"/>
      <geometry>
        <mesh filename="package://silverhand_arm_model/meshes/link_1.STL"/>
      </geometry>
      <material name="">
        <color rgba="0.80 0.80 0.82 1"/>
      </material>
    </visual>
    <collision>
      <origin rpy="0 0 0" xyz="0 0 0"/>
      <geometry>
        <mesh filename="package://silverhand_arm_model/meshes/link_1.STL"/>
      </geometry>
    </collision>
  </link>
  <joint name="joint_1" type="continuous">
    <origin rpy="3.1416 0 0" xyz="0 0 0"/>
    <parent link="arm_root_link"/>
    <child link="link_1"/>
    <axis xyz="0 0 -1"/>
  </joint>
  <link name="link_2">
    <inertial>
      <origin rpy="0 0 0" xyz="0.064818 -0.11189 -0.038671"/>
      <mass value="0.57738"/>
      <inertia ixx="0.0047312" ixy="0.0022624" ixz="0.00032144" iyy="0.0020836" iyz="-0.00056569" izz="0.0056129"/>
    </inertial>
    <visual>
      <origin rpy="0 0 0" xyz="0 0 0"/>
      <geometry>
        <mesh filename="package://silverhand_arm_model/meshes/link_2.STL"/>
      </geometry>
      <material name="">
        <color rgba="0.80 0.80 0.82 1"/>
      </material>
    </visual>
    <collision>
      <origin rpy="0 0 0" xyz="0 0 0"/>
      <geometry>
        <mesh filename="package://silverhand_arm_model/meshes/link_2.STL"/>
      </geometry>
    </collision>
  </link>
  <joint name="joint_2" type="continuous">
    <origin rpy="1.5708 -0.894 -1.57" xyz="0 0.064146 -0.16608"/>
    <parent link="link_1"/>
    <child link="link_2"/>
    <axis xyz="0 0 -1"/>
  </joint>
  <!-- =============================================== -->
  <!--          big-arm-covers.stl      -->
  <!-- =============================================== -->
  <link name="big_arm_cover_link">
    <inertial>
      <origin rpy="0 0 0" xyz="0.0 0.0 0.0"/>
      <mass value="0.57738"/>
      <inertia ixx="0.0047312" ixy="0.0022624" ixz="0.00032144" iyy="0.0020836" iyz="-0.00056569" izz="0.0056129"/>
    </inertial>
    <visual>
      <origin rpy="0 0 0" xyz="0.0 0. -0.062"/>
      <geometry>
        <mesh filename="package://silverhand_arm_model/meshes/big-arm-covers.STL"/>
      </geometry>
      <material name="black">
        <color rgba="0 0 0 1.0"/>
      </material>
    </visual>
    <collision>
      <origin rpy="0 0 0" xyz="0.0 0 -0.062"/>
      <geometry>
        <mesh filename="package://silverhand_arm_model/meshes/big-arm-covers.STL"/>
      </geometry>
    </collision>
  </link>
  <joint name="big_arm_cover_joint" type="fixed">
    <parent link="link_2"/>
    <child link="big_arm_cover_link"/>
    <origin rpy="0 0 -2.61" xyz="0 0.0 0.0"/>
  </joint>
  <link name="link_3">
    <inertial>
      <origin rpy="0 0 0" xyz="0 -0.023661 -0.04720367321"/>
      <mass value="0.1787"/>
      <inertia ixx="0.0001685" ixy="-2.7713E-05" ixz="5.6885E-06" iyy="0.00012865" iyz="2.9256E-05" izz="0.00020744"/>
    </inertial>
    <visual>
      <origin rpy="0 0 0" xyz="0 0 0"/>
      <geometry>
        <mesh filename="package://silverhand_arm_model/meshes/link_3.STL"/>
      </geometry>
      <material name="">
        <color rgba="0.80 0.80 0.82 1"/>
      </material>
    </visual>
    <collision>
      <origin rpy="0 0 0" xyz="0 0 0"/>
      <geometry>
        <mesh filename="package://silverhand_arm_model/meshes/link_3.STL"/>
      </geometry>
    </collision>
  </link>
  <joint name="joint_3" type="continuous">
    <origin rpy="0 0 2.3588" xyz="0.1525 -0.26414 0"/>
    <parent link="link_2"/>
    <child link="link_3"/>
    <axis xyz="0 0 -1"/>
  </joint>
  <!-- =============================================== -->
  <!--         camera      -->
  <!-- =============================================== -->
  <link name="camera">
    <inertial>
      <origin rpy="0 0 0" xyz="0.0 0.0 0.0"/>
      <mass value="0.57738"/>
      <inertia ixx="0.0047312" ixy="0.0022624" ixz="0.00032144" iyy="0.0020836" iyz="-0.00056569" izz="0.0056129"/>
    </inertial>
    <visual>
      <!-- + вперед по линку к захвату \ вверх от оси вращения \ вбок по короткой стороне линка
                                            углы и размер не трогать. повторить в collision те же числа     -->
      <origin rpy="0 0 0" xyz="0.13 0.06 0.015"/>
      <geometry>
        <box size="0.035 0.08 0.055"/>
      </geometry>
      <material name="black">
        <color rgba="0 0 0 1.0"/>
      </material>
    </visual>
    <collision>
      <origin rpy="0 0 0" xyz="0.13 0.06 0.015"/>
      <geometry>
        <box size="0.035 0.08 0.055"/>
      </geometry>
    </collision>
  </link>
  <joint name="camera" type="fixed">
    <parent link="link_3"/>
    <child link="camera"/>
    <origin rpy="0 0 0" xyz="0 0.0 0.0"/>
  </joint>
  <link name="link_4">
    <inertial>
      <origin rpy="0 0 0" xyz="0 0 -0.074404"/>
      <mass value="0.34936"/>
      <inertia ixx="0.0030532" ixy="-1.8615E-05" ixz="-7.0047E-05" iyy="0.0031033" iyz="-2.3301E-05" izz="0.00022264"/>
    </inertial>
    <visual>
      <origin rpy="0 0 0" xyz="0 0 0"/>
      <geometry>
        <mesh filename="package://silverhand_arm_model/meshes/link_4.STL"/>
      </geometry>
      <material name="">
        <color rgba="0.80 0.80 0.82 1"/>
      </material>
    </visual>
    <collision>
      <origin rpy="0 0 0" xyz="0 0 0"/>
      <geometry>
        <mesh filename="package://silverhand_arm_model/meshes/link_4.STL"/>
      </geometry>
    </collision>
  </link>
  <joint name="joint_4" type="continuous">
    <origin rpy="1.5708 -1.2554 -1.5708" xyz="0 0 0.00675"/>
    <parent link="link_3"/>
    <child link="link_4"/>
    <axis xyz="0 0 -1"/>
  </joint>
  <!-- =============================================== -->
  <!--         j4-el-tcover      -->
  <!-- =============================================== -->
  <link name="j4-el-tcover">
    <inertial>
      <origin rpy="0 0 0" xyz="0.0 0.0 0.0"/>
      <mass value="0.57738"/>
      <inertia ixx="0.0047312" ixy="0.0022624" ixz="0.00032144" iyy="0.0020836" iyz="-0.00056569" izz="0.0056129"/>
    </inertial>
    <visual>
      <origin rpy="0 3.14 0" xyz="0.0 0.024 0.025"/>
      <geometry>
        <mesh filename="package://silverhand_arm_model/meshes/j4-el-tcover.STL"/>
      </geometry>
      <material name="black">
        <color rgba="0 0 0 1.0"/>
      </material>
    </visual>
    <collision>
      <origin rpy="0 3.14 0" xyz="0.0 0.024 0.025"/>
      <geometry>
        <mesh filename="package://silverhand_arm_model/meshes/j4-el-tcover.STL"/>
      </geometry>
    </collision>
  </link>
  <joint name="j4-el-tcover" type="fixed">
    <parent link="link_4"/>
    <child link="j4-el-tcover"/>
    <origin rpy="0 0 -1.255" xyz="0 0.0 0.0"/>
  </joint>
  <!-- =============================================== -->
  <!--         j5-cover.STL      -->
  <!-- =============================================== -->
  <link name="j5-cover">
    <inertial>
      <origin rpy="0 0 0" xyz="0 0 0.0"/>
      <mass value="0.57738"/>
      <inertia ixx="0.0047312" ixy="0.0022624" ixz="0.00032144" iyy="0.0020836" iyz="-0.00056569" izz="0.0056129"/>
    </inertial>
    <visual>
      <origin rpy="-1.57 1.57 0" xyz="0.08 0.037 -0.14"/>
      <geometry>
        <mesh filename="package://silverhand_arm_model/meshes/j5-cover.STL"/>
      </geometry>
      <material name="black">
        <color rgba="0 0 0 1.0"/>
      </material>
    </visual>
    <collision>
      <origin rpy="-1.57 1.57 0" xyz="0.08 0.037 -0.14"/>
      <geometry>
        <mesh filename="package://silverhand_arm_model/meshes/j5-cover.STL"/>
      </geometry>
    </collision>
  </link>
  <joint name="j5-cover" type="fixed">
    <parent link="link_4"/>
    <child link="j5-cover"/>
    <origin rpy="0 0 -1.255" xyz="0 0.0 0.0"/>
  </joint>
  <link name="link_5">
    <inertial>
      <origin rpy="0 0 0" xyz="0.0015066 0 -0.012585"/>
      <mass value="0.11562"/>
      <inertia ixx="5.5035E-05" ixy="-1.019E-08" ixz="-2.6243E-06" iyy="8.2921E-05" iyz="1.4437E-08" izz="5.2518E-05"/>
    </inertial>
    <visual>
      <origin rpy="0 0 0" xyz="0 0 0"/>
      <geometry>
        <mesh filename="package://silverhand_arm_model/meshes/link_5.STL"/>
      </geometry>
      <material name="">
        <color rgba="0.80 0.80 0.82 1"/>
      </material>
    </visual>
    <collision>
      <origin rpy="0 0 0" xyz="0 0 0"/>
      <geometry>
        <mesh filename="package://silverhand_arm_model/meshes/link_5.STL"/>
      </geometry>
    </collision>
  </link>
  <joint name="joint_5" type="continuous">
    <origin rpy="3.14 0 -2.8262" xyz="0 0 -0.22225"/>
    <parent link="link_4"/>
    <child link="link_5"/>
    <axis xyz="1 0 0"/>
  </joint>
  <link name="link_6">
    <inertial>
      <origin rpy="0 0 0" xyz="0 0 0.01"/>
      <mass value="0.013863"/>
      <inertia ixx="1.3596E-06" ixy="3.0585E-13" ixz="5.7102E-14" iyy="1.7157E-06" iyz="6.3369E-09" izz="2.4332E-06"/>
    </inertial>
    <visual>
      <origin rpy="0 0 0" xyz="0 0 0"/>
      <geometry>
        <mesh filename="package://silverhand_arm_model/meshes/link_6.STL"/>
      </geometry>
      <material name="">
        <color rgba="0.80 0.80 0.82 1"/>
      </material>
    </visual>
    <collision>
      <origin rpy="0 0 0" xyz="0 0 0"/>
      <geometry>
        <mesh filename="package://silverhand_arm_model/meshes/link_6.STL"/>
      </geometry>
    </collision>
  </link>
  <joint name="joint_6" type="continuous">
    <origin rpy="0 0 0" xyz="0 0 0.02117"/>
    <parent link="link_5"/>
    <child link="link_6"/>
    <axis xyz="0 0 1"/>
  </joint>
</robot>
