<?xml version="1.0" ?>
<!-- =================================================================================== -->
<!-- |    This document was autogenerated by xacro from /home/r/silver_ws/src/silverhand_system_description/urdf/silverhand_system.urdf.xacro | -->
<!-- |    EDITING THIS FILE BY HAND IS NOT RECOMMENDED                                 | -->
<!-- =================================================================================== -->
<robot name="silverhand_system">
  <!-- ===================== -->
  <!-- Общие параметры       -->
  <!-- ===================== -->
  <!-- ===================== -->
  <!-- Параметры компоновки  -->
  <!-- ===================== -->
  <!-- Система координат:
       x - вперед
       y - влево
       z - вверх
  -->
  <!-- ===================== -->
  <!-- Сдвиги STL внутри link -->
  <!-- ===================== -->
  <!-- Начни с нулей. Потом правь именно их,
       если сам mesh внутри link сидит криво. -->
  <!-- Если правая сторона окажется вывернутой,
       попробуй для правой стороны в visual поставить:
       0 ${PI} 0
       или
       0 0 ${PI}
  -->
  <!-- ===================== -->
  <!-- Материалы             -->
  <!-- ===================== -->
  <material name="gray">
    <color rgba="0.75 0.75 0.75 1.0"/>
  </material>
  <material name="dark">
    <color rgba="0.25 0.25 0.25 1.0"/>
  </material>
  <!-- ===================== -->
  <!-- Макросы               -->
  <!-- ===================== -->
  <!-- ===================== -->
  <!-- База                  -->
  <!-- ===================== -->
  <link name="base_footprint"/>
  <joint name="base_footprint_to_base_link_joint" type="fixed">
    <parent link="base_footprint"/>
    <child link="base_link"/>
    <origin rpy="0 0 0" xyz="0 0 0.350738"/>
  </joint>
  <link name="base_link">
    <visual>
      <origin rpy="1.5707963267948966 0 1.5707963267948966" xyz="-0.017 0 -0.162"/>
      <geometry>
        <mesh filename="package://silverhand_rover_model/meshes/Body.stl" scale="0.001 0.001 0.001"/>
      </geometry>
      <material name="gray"/>
    </visual>
    <collision>
      <origin rpy="1.5707963267948966 0 1.5707963267948966" xyz="-0.017 0 -0.162"/>
      <geometry>
        <mesh filename="package://silverhand_rover_model/meshes/Body.stl" scale="0.001 0.001 0.001"/>
      </geometry>
    </collision>
    <inertial>
      <origin rpy="0 0 0" xyz="0 0 0"/>
      <mass value="5.0"/>
      <inertia ixx="0.19266666666666665" ixy="0.0" ixz="0.0" iyy="0.39533333333333337" iyz="0.0" izz="0.5026666666666667"/>
    </inertial>
  </link>
  <!-- Центральный visual-узел.
       Пока просто декоративно/визуально.
       Если потом захочешь честную механику дифференциала,
       его уже можно будет перестроить. -->
  <link name="differential_visual_link">
    <visual>
      <origin rpy="1.5707963267948966 0 1.5707963267948966" xyz="0 0 0"/>
      <geometry>
        <mesh filename="package://silverhand_rover_model/meshes/Differential.stl" scale="0.001 0.001 0.001"/>
      </geometry>
      <material name="dark"/>
    </visual>
    <collision>
      <origin rpy="1.5707963267948966 0 1.5707963267948966" xyz="0 0 0"/>
      <geometry>
        <mesh filename="package://silverhand_rover_model/meshes/Differential.stl" scale="0.001 0.001 0.001"/>
      </geometry>
    </collision>
    <inertial>
      <origin rpy="0 0 0" xyz="0 0 0"/>
      <mass value="0.8"/>
      <inertia ixx="0.029226666666666668" ixy="0.0" ixz="0.0" iyy="0.02402666666666667" iyz="0.0" izz="0.005253333333333335"/>
    </inertial>
  </link>
  <joint name="base_to_differential_visual_joint" type="fixed">
    <parent link="base_link"/>
    <child link="differential_visual_link"/>
    <origin rpy="0 0 0" xyz="-0.1769 0 0.111"/>
  </joint>
  <link name="left_leg_visual_link">
    <visual>
      <origin rpy="1.5707963267948966 0 4.71238898038469" xyz="0 0 0"/>
      <geometry>
        <mesh filename="package://silverhand_rover_model/meshes/Leg.stl" scale="0.001 0.001 0.001"/>
      </geometry>
      <material name="gray"/>
    </visual>
    <collision>
      <origin rpy="1.5707963267948966 0 4.71238898038469" xyz="0 0 0"/>
      <geometry>
        <mesh filename="package://silverhand_rover_model/meshes/Leg.stl" scale="0.001 0.001 0.001"/>
      </geometry>
    </collision>
  </link>
  <joint name="base_to_left_leg_visual_joint" type="fixed">
    <parent link="base_link"/>
    <child link="left_leg_visual_link"/>
    <origin rpy="0 0 0" xyz="0.053 0.285 -0.029"/>
  </joint>
  <link name="right_leg_visual_link">
    <visual>
      <origin rpy="1.5707963267948966 0 4.71238898038469" xyz="0 0 0"/>
      <geometry>
        <mesh filename="package://silverhand_rover_model/meshes/Leg.stl" scale="0.001 0.001 0.001"/>
      </geometry>
      <material name="gray"/>
    </visual>
    <collision>
      <origin rpy="1.5707963267948966 0 4.71238898038469" xyz="0 0 0"/>
      <geometry>
        <mesh filename="package://silverhand_rover_model/meshes/Leg.stl" scale="0.001 0.001 0.001"/>
      </geometry>
    </collision>
  </link>
  <joint name="base_to_right_leg_visual_joint" type="fixed">
    <parent link="base_link"/>
    <child link="right_leg_visual_link"/>
    <origin rpy="0 0 0" xyz="0.053 -0.285 -0.029"/>
  </joint>
  <!-- ===================== -->
  <!-- Левая и правая сторона -->
  <!-- ===================== -->
  <!-- ROCKER -->
  <link name="left_rocker_link">
    <inertial>
      <origin rpy="0 0 0" xyz="0 0 0"/>
      <mass value="0.7"/>
      <inertia ixx="0.0016391666666666666" ixy="0.0" ixz="0.0" iyy="0.01082666666666667" iyz="0.0" izz="0.009479166666666669"/>
    </inertial>
  </link>
  <joint name="base_to_left_rocker_joint" type="revolute">
    <parent link="base_link"/>
    <child link="left_rocker_link"/>
    <origin rpy="0 0 0" xyz="0.1 0.355 -0.1"/>
    <!-- Rocker качается в продольной плоскости -->
    <axis xyz="0 1 0"/>
    <limit effort="50" lower="-1.2" upper="1.2" velocity="2.0"/>
    <dynamics damping="0.5" friction="0.1"/>
  </joint>
  <!-- BOGIE -->
  <link name="left_bogie_link">
    <inertial>
      <origin rpy="0 0 0" xyz="0 0 0"/>
      <mass value="0.6"/>
      <inertia ixx="0.001105" ixy="0.0" ixz="0.0" iyy="0.007104999999999999" iyz="0.0" izz="0.006249999999999999"/>
    </inertial>
  </link>
  <joint name="left_rocker_to_left_bogie_joint" type="revolute">
    <parent link="left_rocker_link"/>
    <child link="left_bogie_link"/>
    <origin rpy="0 0 0" xyz="-0.25 0.0 0.0"/>
    <axis xyz="0 1 0"/>
    <limit effort="50" lower="-1.2" upper="1.2" velocity="2.0"/>
    <dynamics damping="0.5" friction="0.1"/>
  </joint>
  <link name="left_front_wheel_link">
    <visual>
      <origin rpy="-1.5707963267948966 -0.890121786 0" xyz="-0.10706 -0.088 0.09654"/>
      <geometry>
        <mesh filename="package://silverhand_rover_model/meshes/Wheel.stl" scale="0.001 0.001 0.001"/>
      </geometry>
      <material name="dark"/>
    </visual>
    <collision>
      <origin rpy="-1.5707963267948966 -0.890121786 0" xyz="-0.10706 -0.088 0.09654"/>
      <geometry>
        <mesh filename="package://silverhand_rover_model/meshes/Wheel.stl" scale="0.001 0.001 0.001"/>
      </geometry>
    </collision>
    <inertial>
      <origin rpy="0 0 0" xyz="0 0 0"/>
      <mass value="0.35"/>
      <!-- Цилиндр с осью вдоль Y -->
      <inertia ixx="0.002461982541666667" ixy="0.0" ixz="0.0" iyy="0.0028181317500000007" iyz="0.0" izz="0.002461982541666667"/>
    </inertial>
  </link>
  <joint name="left_front_wheel_joint" type="continuous">
    <parent link="left_rocker_link"/>
    <child link="left_front_wheel_link"/>
    <origin rpy="0 0 0" xyz="0.3 0.0 -0.22"/>
    <axis xyz="0 1 0"/>
    <dynamics damping="0.2" friction="0.05"/>
  </joint>
  <link name="left_middle_wheel_link">
    <visual>
      <origin rpy="-1.5707963267948966 -0.928081215 0" xyz="0.10790 -0.088 0.09683"/>
      <geometry>
        <mesh filename="package://silverhand_rover_model/meshes/Wheel.stl" scale="0.001 0.001 0.001"/>
      </geometry>
      <material name="dark"/>
    </visual>
    <collision>
      <origin rpy="-1.5707963267948966 -0.928081215 0" xyz="0.10790 -0.088 0.09683"/>
      <geometry>
        <mesh filename="package://silverhand_rover_model/meshes/Wheel.stl" scale="0.001 0.001 0.001"/>
      </geometry>
    </collision>
    <inertial>
      <origin rpy="0 0 0" xyz="0 0 0"/>
      <mass value="0.35"/>
      <!-- Цилиндр с осью вдоль Y -->
      <inertia ixx="0.002461982541666667" ixy="0.0" ixz="0.0" iyy="0.0028181317500000007" iyz="0.0" izz="0.002461982541666667"/>
    </inertial>
  </link>
  <joint name="left_middle_wheel_joint" type="continuous">
    <parent link="left_bogie_link"/>
    <child link="left_middle_wheel_link"/>
    <origin rpy="0 0 0" xyz="0.02 0.0 -0.22"/>
    <axis xyz="0 1 0"/>
    <dynamics damping="0.2" friction="0.05"/>
  </joint>
  <link name="left_rear_wheel_link">
    <visual>
      <origin rpy="-1.5707963267948966 0.869224977 0" xyz="0.14377 -0.088 0.09623"/>
      <geometry>
        <mesh filename="package://silverhand_rover_model/meshes/Wheel.stl" scale="0.001 0.001 0.001"/>
      </geometry>
      <material name="dark"/>
    </visual>
    <collision>
      <origin rpy="-1.5707963267948966 0.869224977 0" xyz="0.14377 -0.088 0.09623"/>
      <geometry>
        <mesh filename="package://silverhand_rover_model/meshes/Wheel.stl" scale="0.001 0.001 0.001"/>
      </geometry>
    </collision>
    <inertial>
      <origin rpy="0 0 0" xyz="0 0 0"/>
      <mass value="0.35"/>
      <!-- Цилиндр с осью вдоль Y -->
      <inertia ixx="0.002461982541666667" ixy="0.0" ixz="0.0" iyy="0.0028181317500000007" iyz="0.0" izz="0.002461982541666667"/>
    </inertial>
  </link>
  <joint name="left_rear_wheel_joint" type="continuous">
    <parent link="left_bogie_link"/>
    <child link="left_rear_wheel_link"/>
    <origin rpy="0 0 0" xyz="-0.32 0.0 -0.22"/>
    <axis xyz="0 1 0"/>
    <dynamics damping="0.2" friction="0.05"/>
  </joint>
  <!-- ROCKER -->
  <link name="right_rocker_link">
    <inertial>
      <origin rpy="0 0 0" xyz="0 0 0"/>
      <mass value="0.7"/>
      <inertia ixx="0.0016391666666666666" ixy="0.0" ixz="0.0" iyy="0.01082666666666667" iyz="0.0" izz="0.009479166666666669"/>
    </inertial>
  </link>
  <joint name="base_to_right_rocker_joint" type="revolute">
    <parent link="base_link"/>
    <child link="right_rocker_link"/>
    <origin rpy="0 0 0" xyz="0.1 -0.355 -0.1"/>
    <!-- Rocker качается в продольной плоскости -->
    <axis xyz="0 1 0"/>
    <limit effort="50" lower="-1.2" upper="1.2" velocity="2.0"/>
    <dynamics damping="0.5" friction="0.1"/>
  </joint>
  <!-- BOGIE -->
  <link name="right_bogie_link">
    <inertial>
      <origin rpy="0 0 0" xyz="0 0 0"/>
      <mass value="0.6"/>
      <inertia ixx="0.001105" ixy="0.0" ixz="0.0" iyy="0.007104999999999999" iyz="0.0" izz="0.006249999999999999"/>
    </inertial>
  </link>
  <joint name="right_rocker_to_right_bogie_joint" type="revolute">
    <parent link="right_rocker_link"/>
    <child link="right_bogie_link"/>
    <origin rpy="0 0 0" xyz="-0.25 0.0 0.0"/>
    <axis xyz="0 1 0"/>
    <limit effort="50" lower="-1.2" upper="1.2" velocity="2.0"/>
    <dynamics damping="0.5" friction="0.1"/>
  </joint>
  <link name="right_front_wheel_link">
    <visual>
      <origin rpy="-1.5707963267948966 0.890121786 3.141592653589793" xyz="-0.10706 0.088 0.09654"/>
      <geometry>
        <mesh filename="package://silverhand_rover_model/meshes/Wheel.stl" scale="0.001 0.001 0.001"/>
      </geometry>
      <material name="dark"/>
    </visual>
    <collision>
      <origin rpy="-1.5707963267948966 0.890121786 3.141592653589793" xyz="-0.10706 0.088 0.09654"/>
      <geometry>
        <mesh filename="package://silverhand_rover_model/meshes/Wheel.stl" scale="0.001 0.001 0.001"/>
      </geometry>
    </collision>
    <inertial>
      <origin rpy="0 0 0" xyz="0 0 0"/>
      <mass value="0.35"/>
      <!-- Цилиндр с осью вдоль Y -->
      <inertia ixx="0.002461982541666667" ixy="0.0" ixz="0.0" iyy="0.0028181317500000007" iyz="0.0" izz="0.002461982541666667"/>
    </inertial>
  </link>
  <joint name="right_front_wheel_joint" type="continuous">
    <parent link="right_rocker_link"/>
    <child link="right_front_wheel_link"/>
    <origin rpy="0 0 0" xyz="0.3 0.0 -0.22"/>
    <axis xyz="0 1 0"/>
    <dynamics damping="0.2" friction="0.05"/>
  </joint>
  <link name="right_middle_wheel_link">
    <visual>
      <origin rpy="-1.5707963267948966 0.928081215 3.141592653589793" xyz="0.10790 0.088 0.09683"/>
      <geometry>
        <mesh filename="package://silverhand_rover_model/meshes/Wheel.stl" scale="0.001 0.001 0.001"/>
      </geometry>
      <material name="dark"/>
    </visual>
    <collision>
      <origin rpy="-1.5707963267948966 0.928081215 3.141592653589793" xyz="0.10790 0.088 0.09683"/>
      <geometry>
        <mesh filename="package://silverhand_rover_model/meshes/Wheel.stl" scale="0.001 0.001 0.001"/>
      </geometry>
    </collision>
    <inertial>
      <origin rpy="0 0 0" xyz="0 0 0"/>
      <mass value="0.35"/>
      <!-- Цилиндр с осью вдоль Y -->
      <inertia ixx="0.002461982541666667" ixy="0.0" ixz="0.0" iyy="0.0028181317500000007" iyz="0.0" izz="0.002461982541666667"/>
    </inertial>
  </link>
  <joint name="right_middle_wheel_joint" type="continuous">
    <parent link="right_bogie_link"/>
    <child link="right_middle_wheel_link"/>
    <origin rpy="0 0 0" xyz="0.02 0.0 -0.22"/>
    <axis xyz="0 1 0"/>
    <dynamics damping="0.2" friction="0.05"/>
  </joint>
  <link name="right_rear_wheel_link">
    <visual>
      <origin rpy="-1.5707963267948966 -0.869224977 3.141592653589793" xyz="0.14377 0.088 0.09623"/>
      <geometry>
        <mesh filename="package://silverhand_rover_model/meshes/Wheel.stl" scale="0.001 0.001 0.001"/>
      </geometry>
      <material name="dark"/>
    </visual>
    <collision>
      <origin rpy="-1.5707963267948966 -0.869224977 3.141592653589793" xyz="0.14377 0.088 0.09623"/>
      <geometry>
        <mesh filename="package://silverhand_rover_model/meshes/Wheel.stl" scale="0.001 0.001 0.001"/>
      </geometry>
    </collision>
    <inertial>
      <origin rpy="0 0 0" xyz="0 0 0"/>
      <mass value="0.35"/>
      <!-- Цилиндр с осью вдоль Y -->
      <inertia ixx="0.002461982541666667" ixy="0.0" ixz="0.0" iyy="0.0028181317500000007" iyz="0.0" izz="0.002461982541666667"/>
    </inertial>
  </link>
  <joint name="right_rear_wheel_joint" type="continuous">
    <parent link="right_bogie_link"/>
    <child link="right_rear_wheel_link"/>
    <origin rpy="0 0 0" xyz="-0.32 0.0 -0.22"/>
    <axis xyz="0 1 0"/>
    <dynamics damping="0.2" friction="0.05"/>
  </joint>
  <!-- Рука установлена на нижней передней панели.
       По Y центрирована на площадке, по X подведена так, чтобы задняя
       часть первого линка подходила к вертикальной стенке ровера. -->
  <link name="arm_mount_link"/>
  <joint name="base_to_arm_mount_joint" type="fixed">
    <parent link="base_link"/>
    <child link="arm_mount_link"/>
    <origin rpy="0 0 0" xyz="0.324 0.0 -0.076"/>
  </joint>
  <link name="arm_base_link"/>
  <link name="arm_arm_root_link">
    <inertial>
      <origin rpy="0 0 0" xyz="-4.6941E-06 0.054174 0.038824"/>
      <mass value="0.7102"/>
      <inertia ixx="0.0039943" ixy="3.697E-07" ixz="-5.7364E-08" iyy="0.0014946" iyz="-0.00036051" izz="0.0042554"/>
    </inertial>
    <visual>
      <origin rpy="0 0 0" xyz="0 0 0"/>
      <geometry>
        <mesh filename="package://silverhand_arm_model/meshes/base_link.STL"/>
      </geometry>
      <material name="">
        <color rgba="0.80 0.80 0.82 1"/>
      </material>
    </visual>
    <collision>
      <origin rpy="0 0 0" xyz="0 0 0"/>
      <geometry>
        <mesh filename="package://silverhand_arm_model/meshes/base_link.STL"/>
      </geometry>
    </collision>
  </link>
  <joint name="arm_mount_joint" type="fixed">
    <origin rpy="0 0 0" xyz="0 0 0"/>
    <parent link="arm_mount_link"/>
    <child link="arm_base_link"/>
  </joint>
  <joint name="arm_arm_root_joint" type="fixed">
    <origin rpy="0 0 1.5708" xyz="0 0 0"/>
    <parent link="arm_base_link"/>
    <child link="arm_arm_root_link"/>
  </joint>
  <link name="arm_link_1">
    <inertial>
      <origin rpy="0 0 0" xyz="-0.022706 0.04294 -0.12205"/>
      <mass value="0.88065"/>
      <inertia ixx="0.0034" ixy="0.00042296" ixz="-0.00089231" iyy="0.0041778" iyz="0.0010848" izz="0.0027077"/>
    </inertial>
    <visual>
      <origin rpy="0 0 0" xyz="0 0 0"/>
      <geometry>
        <mesh filename="package://silverhand_arm_model/meshes/link_1.STL"/>
      </geometry>
      <material name="">
        <color rgba="0.80 0.80 0.82 1"/>
      </material>
    </visual>
    <collision>
      <origin rpy="0 0 0" xyz="0 0 0"/>
      <geometry>
        <mesh filename="package://silverhand_arm_model/meshes/link_1.STL"/>
      </geometry>
    </collision>
  </link>
  <joint name="arm_joint_1" type="continuous">
    <origin rpy="3.1416 0 0" xyz="0 0 0.003445"/>
    <parent link="arm_arm_root_link"/>
    <child link="arm_link_1"/>
    <axis xyz="0 0 1"/>
  </joint>
  <link name="arm_link_2">
    <inertial>
      <origin rpy="0 0 0" xyz="0.064818 -0.11189 -0.038671"/>
      <mass value="0.57738"/>
      <inertia ixx="0.0047312" ixy="0.0022624" ixz="0.00032144" iyy="0.0020836" iyz="-0.00056569" izz="0.0056129"/>
    </inertial>
    <visual>
      <origin rpy="0 0 0" xyz="0 0 0"/>
      <geometry>
        <mesh filename="package://silverhand_arm_model/meshes/link_2.STL"/>
      </geometry>
      <material name="">
        <color rgba="0.80 0.80 0.82 1"/>
      </material>
    </visual>
    <collision>
      <origin rpy="0 0 0" xyz="0 0 0"/>
      <geometry>
        <mesh filename="package://silverhand_arm_model/meshes/link_2.STL"/>
      </geometry>
    </collision>
  </link>
  <joint name="arm_joint_2" type="continuous">
    <origin rpy="1.5708 -1.0472 -1.5708" xyz="0 0.064146 -0.16608"/>
    <parent link="arm_link_1"/>
    <child link="arm_link_2"/>
    <axis xyz="0 0 -1"/>
  </joint>
  <link name="arm_link_3">
    <inertial>
      <origin rpy="0 0 0" xyz="-0.00029765 -0.023661 -1.04720367321"/>
      <mass value="0.1787"/>
      <inertia ixx="0.0001685" ixy="-2.7713E-05" ixz="5.6885E-06" iyy="0.00012865" iyz="2.9256E-05" izz="0.00020744"/>
    </inertial>
    <visual>
      <origin rpy="0 0 0" xyz="0 0 0"/>
      <geometry>
        <mesh filename="package://silverhand_arm_model/meshes/link_3.STL"/>
      </geometry>
      <material name="">
        <color rgba="0.80 0.80 0.82 1"/>
      </material>
    </visual>
    <collision>
      <origin rpy="0 0 0" xyz="0 0 0"/>
      <geometry>
        <mesh filename="package://silverhand_arm_model/meshes/link_3.STL"/>
      </geometry>
    </collision>
  </link>
  <joint name="arm_joint_3" type="continuous">
    <origin rpy="0 0 2.0708" xyz="0.1525 -0.26414 0"/>
    <parent link="arm_link_2"/>
    <child link="arm_link_3"/>
    <axis xyz="0 0 -1"/>
  </joint>
  <link name="arm_link_4">
    <inertial>
      <origin rpy="0 0 0" xyz="-0.0016798 -0.00057319 -0.074404"/>
      <mass value="0.34936"/>
      <inertia ixx="0.0030532" ixy="-1.8615E-05" ixz="-7.0047E-05" iyy="0.0031033" iyz="-2.3301E-05" izz="0.00022264"/>
    </inertial>
    <visual>
      <origin rpy="0 0 0" xyz="0 0 0"/>
      <geometry>
        <mesh filename="package://silverhand_arm_model/meshes/link_4.STL"/>
      </geometry>
      <material name="">
        <color rgba="0.80 0.80 0.82 1"/>
      </material>
    </visual>
    <collision>
      <origin rpy="0 0 0" xyz="0 0 0"/>
      <geometry>
        <mesh filename="package://silverhand_arm_model/meshes/link_4.STL"/>
      </geometry>
    </collision>
  </link>
  <joint name="arm_joint_4" type="continuous">
    <origin rpy="1.5708 -1.2554 -1.5708" xyz="0 0 0.00675"/>
    <parent link="arm_link_3"/>
    <child link="arm_link_4"/>
    <axis xyz="0 0 -1"/>
  </joint>
  <link name="arm_link_5">
    <inertial>
      <origin rpy="0 0 0" xyz="0.0015066 -1.3102E-05 -0.012585"/>
      <mass value="0.11562"/>
      <inertia ixx="5.5035E-05" ixy="-1.019E-08" ixz="-2.6243E-06" iyy="8.2921E-05" iyz="1.4437E-08" izz="5.2518E-05"/>
    </inertial>
    <visual>
      <origin rpy="0 0 0" xyz="0 0 0"/>
      <geometry>
        <mesh filename="package://silverhand_arm_model/meshes/link_5.STL"/>
      </geometry>
      <material name="">
        <color rgba="0.80 0.80 0.82 1"/>
      </material>
    </visual>
    <collision>
      <origin rpy="0 0 0" xyz="0 0 0"/>
      <geometry>
        <mesh filename="package://silverhand_arm_model/meshes/link_5.STL"/>
      </geometry>
    </collision>
  </link>
  <joint name="arm_joint_5" type="continuous">
    <origin rpy="1.5708 0 -2.8262" xyz="0 0 -0.22225"/>
    <parent link="arm_link_4"/>
    <child link="arm_link_5"/>
    <axis xyz="-1 0 0"/>
  </joint>
  <link name="arm_link_6">
    <inertial>
      <origin rpy="0 0 0" xyz="2.9287E-10 -1.6472E-09 0.0091432"/>
      <mass value="0.013863"/>
      <inertia ixx="1.3596E-06" ixy="3.0585E-13" ixz="5.7102E-14" iyy="1.7157E-06" iyz="6.3369E-09" izz="2.4332E-06"/>
    </inertial>
    <visual>
      <origin rpy="0 0 0" xyz="0 0 0"/>
      <geometry>
        <mesh filename="package://silverhand_arm_model/meshes/link_6.STL"/>
      </geometry>
      <material name="">
        <color rgba="0.80 0.80 0.82 1"/>
      </material>
    </visual>
    <collision>
      <origin rpy="0 0 0" xyz="0 0 0"/>
      <geometry>
        <mesh filename="package://silverhand_arm_model/meshes/link_6.STL"/>
      </geometry>
    </collision>
  </link>
  <joint name="arm_joint_6" type="continuous">
    <origin rpy="0 0 -1.5708" xyz="-0.000294 0 0.02117"/>
    <parent link="arm_link_5"/>
    <child link="arm_link_6"/>
    <axis xyz="0 0 1"/>
  </joint>
  <link name="hand_base_link"/>
  <joint name="hand_mount_joint" type="fixed">
    <origin rpy="0 0 0" xyz="0 0 0"/>
    <parent link="arm_link_6"/>
    <child link="hand_base_link"/>
  </joint>
  <link name="hand_gripper_link">
    <inertial>
      <origin rpy="0 0 0" xyz="0.0510509 0.009108 0.0106343"/>
      <mass value="0.01"/>
      <inertia ixx="0.00303336450376" ixy="-0.000437276865508" ixz="0.000629257294877" iyy="0.00404479911567" iyz="0.000130472021025" izz="0.00558234286039"/>
    </inertial>
    <visual>
      <origin rpy="0 0 1.57" xyz="0 0 0"/>
      <geometry>
        <mesh filename="package://silverhand_hand_model/meshes/gripper4310.stl"/>
      </geometry>
      <material name="">
        <color rgba="0.0 0.15 0.85 1"/>
      </material>
    </visual>
    <collision>
      <origin rpy="0 0 1.57" xyz="0 0 0"/>
      <geometry>
        <mesh filename="package://silverhand_hand_model/meshes/gripper4310.stl"/>
      </geometry>
    </collision>
  </link>
  <joint name="hand_base_to_gripper_joint" type="fixed">
    <origin rpy="0 0 0" xyz="0 0 0"/>
    <parent link="hand_base_link"/>
    <child link="hand_gripper_link"/>
  </joint>
  <link name="hand_left_finger">
    <inertial>
      <origin rpy="0 0 0" xyz="0.0510509 0.009108 0.0106343"/>
      <mass value="0.01"/>
      <inertia ixx="0.00303336450376" ixy="-0.000437276865508" ixz="0.000629257294877" iyy="0.00404479911567" iyz="0.000130472021025" izz="0.00558234286039"/>
    </inertial>
    <visual>
      <origin rpy="0 0 0" xyz="0 0 0"/>
      <geometry>
        <mesh filename="package://silverhand_hand_model/meshes/finger50mm-S.stl"/>
      </geometry>
      <material name="">
        <color rgba="0.85 0.85 0.88 1"/>
      </material>
    </visual>
    <collision>
      <origin rpy="0 0 0" xyz="0 0 0"/>
      <geometry>
        <mesh filename="package://silverhand_hand_model/meshes/finger50mm-S.stl"/>
      </geometry>
    </collision>
  </link>
  <joint name="hand_left_finger_joint" type="prismatic">
    <origin rpy="1.57 0 3.14" xyz="0 0.005 0.0642"/>
    <parent link="hand_gripper_link"/>
    <child link="hand_left_finger"/>
    <axis xyz="0 0 1"/>
    <limit effort="20" lower="-0.00001" upper="0.01" velocity="0.2"/>
  </joint>
  <link name="hand_right_finger">
    <inertial>
      <origin rpy="0 0 0" xyz="0.0510509 0.009108 0.0106343"/>
      <mass value="0.01"/>
      <inertia ixx="0.00303336450376" ixy="-0.000437276865508" ixz="0.000629257294877" iyy="0.00404479911567" iyz="0.000130472021025" izz="0.00558234286039"/>
    </inertial>
    <visual>
      <origin rpy="0 0 0" xyz="0 0 0"/>
      <geometry>
        <mesh filename="package://silverhand_hand_model/meshes/finger50mm-S-1.stl"/>
      </geometry>
      <material name="">
        <color rgba="0.85 0.85 0.88 1"/>
      </material>
    </visual>
    <collision>
      <origin rpy="0 0 0" xyz="0 0 0"/>
      <geometry>
        <mesh filename="package://silverhand_hand_model/meshes/finger50mm-S-1.stl"/>
      </geometry>
    </collision>
  </link>
  <joint name="hand_right_finger_joint" type="prismatic">
    <origin rpy="1.57 0 0" xyz="0 -0.005 0.0642"/>
    <parent link="hand_gripper_link"/>
    <child link="hand_right_finger"/>
    <axis xyz="0 0 1"/>
    <limit effort="20" lower="-0.00001" upper="0.01" velocity="0.2"/>
  </joint>
</robot>
